Workbook
Name \T: #REF!
Name __Count: 9
Name _01_01_99: #REF!
Name _01_02_99: #REF!
Name _01_03_99: #REF!
Name _01_04_99: #REF!
Name _01_05_99: #REF!
Name _01_06_99: #REF!
Name _01_07_99: #REF!
Name _01_08_1999: #REF!
Name _01_11_2001: #N/A
Name _0300625210_025_1: #REF!
Name _0301167362_1: #REF!
Name _0600038118_3: #REF!
Name _1: #REF!
Name _1_20001_TblF0902JDE: #REF!
Name _1000A01: #N/A
Name _1111: #REF!
Name _11MAÕ_HAØNG: #REF!
Name _13MAÕ_SOÁ_THUEÁ: #REF!
Name _15ÑÔN_GIAÙ: #REF!
Name _1600377828_1: #REF!
Name _17SOÁ_CTÖØ: #REF!
Name _18SOÁ_LÖÔÏNG: #REF!
Name _1BA2500: #REF!
Name _1BA3250: #REF!
Name _1BA400P: #REF!
Name _1CAP001: #REF!
Name _1CAP011: #REF!
Name _1CAP012: #REF!
Name _1CDHT03: #REF!
Name _1CHANG2: #REF!
Name _1DADOI1: #REF!
Name _1DAU002: #REF!
Name _1DDAY03: #REF!
Name _1DDTT01: #REF!
Name _1FCO101: #REF!
Name _1GIA101: #REF!
Name _1LA1001: #REF!
Name _1MCCBO2: #REF!
Name _1PKCAP1: #REF!
Name _1PKIEN2: #REF!
Name _1PKTT01: #REF!
Name _1TCD101: #REF!
Name _1TCD201: #REF!
Name _1TCD203: #REF!
Name _1TD2001: #REF!
Name _1TIHT01: #REF!
Name _1TIHT06: #REF!
Name _1TIHT07: #REF!
Name _1TRU121: #REF!
Name _2: #REF!
Name _20TEÂN_HAØNG: #REF!
Name _22TEÂN_KHAÙCH_HAØ: #REF!
Name _24THAØNH_TIEÀN: #REF!
Name _26TRÒ_GIAÙ: #REF!
Name _2700138984_1: #REF!
Name _28TRÒ_GIAÙ__VAT: #REF!
Name _2900326167_1: #REF!
Name _2BLA100: #REF!

Sheet EPS,P.E, P.B
B1: Today price | C1: 18200
C3: 2010 | D3: 2011 | E3: 2012 | F3: 2013 | G3: 2014 | H3: 2015 | I3: 2016 | J3: 2017 | K3: 2018 | L3: 2019
B4: NPAT (VND'b) | C4: ='P&L'!C30 -> 72.079287 | D4: ='P&L'!D30 -> 24.591496 | E4: ='P&L'!E30 -> 57.859951 | F4: ='P&L'!F30 -> 82.763994 | G4: ='P&L'!G30 -> 167.83449 | H4: ='P&L'!H30 -> 0.337 | I4: ='P&L'!I30 -> 0.50305051 | J4: ='P&L'!J30 -> 0.73327004 | ... L4: ='P&L'!L30 -> 1.1377904
B5: Year-end share count (mn) | C5: =#REF!/10 -> #REF! | D5: =#REF!/10 -> #REF! | E5: =#REF!/10 -> #REF! | F5: =#REF!/10 -> #REF! | G5: =#REF!/10 -> #REF! | H5: 116.87 | I5: =H5 -> 116.87 | J5: =I5 -> 116.87 | K5: =#REF!/10 -> #REF! | L5: =#REF!/10 -> #REF!
B6: Private placement | D6: 5.2 | E6: 10 | G6: 11.64 | H6: 25.7
B7: ESOP | C7: 0.4 | D7: 0.8 | F7: 0.3 | H7: 0.3
B8: Right issue | C8: 7.6 | D8: 10 | G8: 10.56
B9: Share dividend | F9: 10.4996 | H9: 5.245
B10: Share dividend (to be issued) | H10: 10.625
B11: Adjusted year-end share count | C11: =I11-SUM(D6:J7) -> 62.93 | D11: =I11-SUM(E6:J7) -> 68.93 | E11: =I11-SUM(F6:J7) -> 78.93 | F11: =I11-SUM(G6:J7) -> 79.23 | G11: =I11-SUM(H6:J7) -> 90.87 | H11: =H5-H10 -> 106.245 | I11: =I5 -> 116.87 | J11: =J5 -> 116.87 | K11: =K5 -> #REF! | L11: =L5 -> #REF!
B12: Fully diluted share count | C12: =C11+$H$10 -> 73.555 | D12: =D11+$H$10 -> 79.555 | E12: =E11+$H$10 -> 89.555 | F12: =F11+$H$10 -> 89.855 | G12: =G11+$H$10 -> 101.495 | H12: =H10+H11 -> 116.87 | I12: =H12 -> 116.87 | J12: =I12 -> 116.87
B13: EPS | C13: =C4/C11*1000 -> 1145.3883 | D13: =D4/D11*1000 -> 356.76043 | E13: =E4/E11*1000 -> 733.05399 | F13: =F4/F11*1000 -> 1044.6042 | G13: =G4/G11*1000 -> 1846.9736 | H13: =H4/H12*1000 -> 2.8835458 | I13: =I4/I12*1000 -> 4.3043596 | J13: =J4/J12*1000 -> 6.2742367 | K13: =K4/K11*1000 -> #REF! | L13: =L4/L11*1000 -> #REF!
B15: P/E | C15: =$C$1/C13 -> 15.889808 | D15: =$C$1/D13 -> 51.014627 | E15: =$C$1/E13 -> 24.827639 | F15: =$C$1/F13 -> 17.422866 | G15: =$C$1/G13 -> 9.8539579 | H15: =$C$1/H13 -> 6311.6736 | I15: =$C$1/I13 -> 4228.2712 | J15: =$C$1/J13 -> 2900.7513 | ... L15: =$C$1/L13 -> #REF!
B18: Total Equity | C18: =#REF! -> #REF! | D18: =#REF! -> #REF! | E18: =#REF! -> #REF! | F18: =#REF! -> #REF! | G18: =#REF! -> #REF! | H18: =#REF! -> #REF! | I18: =#REF! -> #REF! | J18: =#REF! -> #REF!
B19: Minority interest | C19: =#REF! -> #REF! | D19: =#REF! -> #REF! | E19: =#REF! -> #REF! | F19: =#REF! -> #REF! | G19: =#REF! -> #REF! | H19: =#REF! -> #REF! | I19: =#REF! -> #REF! | J19: =#REF! -> #REF!
B20: Book value | C20: =(C18-C19)/C11*10^3 -> #REF! | D20: =(D18-D19)/D11*10^3 -> #REF! | E20: =(E18-E19)/E11*10^3 -> #REF! | F20: =(F18-F19)/F11*10^3 -> #REF! | G20: =(G18-G19)/G11*10^3 -> #REF! | H20: =(H18-H19)/H12*10^3 -> #REF! | I20: =(I18-I19)/I12*10^3 -> #REF! | J20: =(J18-J19)/J12*10^3 -> #REF!
B22: P/B | C22: =$C$1/C20 -> #REF! | D22: =$C$1/D20 -> #REF! | E22: =$C$1/E20 -> #REF! | F22: =$C$1/F20 -> #REF! | G22: =$C$1/G20 -> #REF! | H22: =$C$1/H20 -> #REF! | I22: =$C$1/I20 -> #REF! | J22: =$C$1/J20 -> #REF!

Sheet Voulme
A2: 42254 | B2: 16.1 | C2: 16.1 | D2: -0.3 (-1.8 %) | F2: 793220 | G2: 12791000000 | H2: 0 | I2: 0 | J2: 16.3 | K2: 16.4 | L2: 15.9
A3: 42251 | B3: 16.4 | C3: 16.4 | D3: -0.1 (-0.6 %) | F3: 858160 | G3: 14075000000 | H3: 0 | I3: 0 | J3: 16.5 | K3: 16.6 | L3: 16.2
A4: 42250 | B4: 16.5 | C4: 16.5 | D4: -0.3 (-1.8 %) | F4: 1521750 | G4: 25356000000 | H4: 0 | I4: 0 | J4: 16.7 | K4: 17 | L4: 16.4
A5: 42248 | B5: 16.8 | C5: 16.8 | D5: 0.9 (5.7 %) | F5: 1980100 | G5: 32790000000 | H5: 0 | I5: 0 | J5: 15.8 | K5: 17 | L5: 15.8
A6: 42247 | B6: 15.9 | C6: 15.9 | D6: -0.4 (-2.5 %) | F6: 1335790 | G6: 21301000000 | H6: 0 | I6: 0 | J6: 16.1 | K6: 16.2 | L6: 15.8
A7: 42244 | B7: 16.3 | C7: 16.3 | D7: 0.2 (1.2 %) | F7: 1437130 | G7: 23200000000 | H7: 0 | I7: 0 | J7: 16.4 | K7: 16.4 | L7: 15.9
A8: 42243 | B8: 16.1 | C8: 16.1 | D8: 0.5 (3.2 %) | F8: 2543790 | G8: 40979000000 | H8: 50000 | I8: 830000000 | J8: 16 | K8: 16.3 | L8: 16
A9: 42242 | B9: 15.6 | C9: 15.6 | D9: 1.0 (6.8 %) | F9: 2470020 | G9: 37976000000 | H9: 70000 | I9: 1050000000 | J9: 14.8 | K9: 15.6 | L9: 14.8
A10: 42241 | B10: 14.6 | C10: 14.6 | D10: -0.7 (-4.6 %) | F10: 2569560 | G10: 37706000000 | H10: 0 | I10: 0 | J10: 14.4 | K10: 15.3 | L10: 14.3
A11: 42240 | B11: 15.3 | C11: 15.3 | D11: -1.1 (-6.7 %) | F11: 1865240 | G11: 28758000000 | H11: 0 | I11: 0 | J11: 15.9 | K11: 16 | L11: 15.3
A12: 42237 | B12: 16.4 | C12: 16.4 | D12: -0.3 (-1.8 %) | F12: 2457840 | G12: 39270000000 | H12: 0 | I12: 0 | J12: 16.4 | K12: 16.4 | L12: 15.6
A13: 42236 | B13: 16.7 | C13: 16.7 | D13: -0.2 (-1.2 %) | F13: 1381340 | G13: 23238000000 | H13: 0 | I13: 0 | J13: 16.9 | K13: 17.1 | L13: 16.6
... A31: 42212 | B31: 18.8 | C31: 18.8 | D31: 0.3 (1.6 %) | F31: 1531510 | G31: 28477000000 | H31: 0 | I31: 0 | J31: 18.4 | K31: 18.8 | L31: 18.4
G34: =SUM(G2:G31) -> 910022000000 | I34: =SUM(I2:I31) -> 1880000000
F36: =SUM(F34:I34)/30 -> 3.0396733e+10
F37: =F36/21890 -> 1388612.8
F38: =F37/10^6 -> 1.3886128

Sheet EPS
A1: 3 | B1: EPS AND P/E CALCULATION TEMPLATE | M1: IMPORTANT NOTES:
B2: NOTE: | C2: figures in blue font should be hard-coded in manually; figures in black font are automatically calculated | M2: It is necessary to treat Rights Issues as dilutive because the rights can be transfered and results in a change in capital - similar to a new issuance where the original shareholder will be diluted.
C4: COMPANY TICKER | D4: DXG | M4: The bonus element of rights issue must be calculated. The bonus shares must be added to prior periods. If this is not done, EPS growth will be "penalized" for those shares. Refer to theorectical ex-rights price calculation. In this example for DXG, this HAS NOT been done yet.
G5: UPCOMING RIGHTS ISSUE IN 2016
C6: Current share price | D6: =Valuation!#REF! -> #REF! | G6: Rights Issue/Placement | J6: 0 | M6: We will forego time adjustments and will assume capital is raised at the beginning of the year. This is to "contain" the full dilution impact within the same year. Using weighted average will allow the dilution to "spill over" resulting in lower EPS growth in the following year. I feel it is more important to understand the what is happening in terms of capital changes versus pursuing pinpoint accuracy. To see an example of this effect change Time Weight from 100% to 50% in year to 2013 then check impact on EPS growth vs. NPAT growth.
C7: Theorectical Ex-Rights Price | D7: =Valuation!#REF! -> #REF! | G7: Exercise Price | J7: 10000
C8: Include upcoming Rights Issue | D8: No | G8: Fair value shares | J8: =(J6*J7)/D6 -> #REF! | M8: If we include upcoming share expansions that result in change in capital, it is necessary to adjust the stock price to calculate multiples.
C9: Current reporting year | D9: 2015 | G9: Bonus element | J9: =J6-J8 -> #REF! | M9: If upcoming share expansion does not result in change in capital, use market price, as there will be no changes in EPS growth or PER.
D11: Historical | I11: Forecast
D12: =$D$9-5 -> 2010 | E12: =D12+1 -> 2011 | F12: =E12+1 -> 2012 | G12: =F12+1 -> 2013 | H12: =G12+1 -> 2014 | I12: =H12+1 -> 2015 | J12: =I12+1 -> 2016 | K12: =J12+1 -> 2017
C13: TIME WEIGHT | D13: 1 | E13: 1 | F13: 1 | G13: 1 | H13: 1 | I13: 1 | J13: 1 | K13: 1
C14: NPAT less MI, adjusted | D14: ='P&L'!C32-D15 -> 66.531287 | E14: ='P&L'!D32-E15 -> 18.887496 | F14: ='P&L'!E32-F15 -> 54.551951 | G14: ='P&L'!F32-G15 -> 47.291502 | H14: ='P&L'!G32-H15 -> 94.563846 | I14: ='P&L'!H32-I15 -> 0.2473 | J14: ='P&L'!I32-J15 -> 0.41859244 | K14: ='P&L'!J32-K15 -> 0.64232233 | M14: NPAT less Minority Interest, excluding after tax exceptional items and deduct contribution to employee bonus
C15: --> Adj of bonus welfare fund (C200) | D15: 5.548 | E15: 5.704 | F15: 3.308 | G15: 5.682 | H15: 19.363 | I15: ='P&L'!H30*10% -> 0.0337 | J15: ='P&L'!I30*10% -> 0.050305051 | K15: ='P&L'!J30*10% -> 0.073327004
C16: Begin | D16: 8 | E16: 16 | F16: 32 | G16: 42 | H16: 52.799681 | I16: 75 | J16: =I25 -> #REF! | K16: =J25 -> #REF!
C17: Breakdown of new shares added each year:
B18: Dilutive - Change in capital resources | C18: Private placement | E18: 5.2 | F18: 10 | H18: 11.64 | I18: 25.7
C19: Follow-on share offerings
C20: Rights issue (fair value) | D20: 6.6 | E20: 9 | H20: 8 | J20: =IF(D8="YES",J8,0) -> 0 | M20: Note I have made abitrary changes to completed rights issues i.e split fair and bonus to illustrate. These are not actual figures. Rights issue for 2016 is properly calculated
B21: Non-Dilutive - no change in capital resources | C21: Rights issue (bonus element) | D21: 1 | E21: 1 | H21: 2.6 | J21: =IF(D8="YES",J9,0) -> 0
C22: Share dividend | G22: 10.4996 | I22: =5.545+10.6 -> 16.145 | M22: For further reference see link below.
C23: Bonus shares | M23: http://accounting-simplified.com/ifrs/ias-33-eps/basic/rights-issue.html#adjustment
C25: Year end count unadjusted | D25: =SUM(D16:D23) -> 15.6 | E25: =SUM(E16:E23) -> 31.2 | F25: =SUM(F16:F23) -> 42 | G25: =SUM(G16:G23) -> 52.4996 | H25: =SUM(H16:H23) -> 75.039681 | I25: =Equity!#REF! -> #REF! | J25: =Equity!#REF! -> #REF! | K25: =Equity!#REF! -> #REF!
C26: Adjusted share count (m) | D26: =D16+(D13* SUM(D18:D20))+SUM(D21:$J23) -> 45.8446 | E26: =E16+(E13* SUM(E18:E20))+SUM(E21:$J23) -> 60.4446 | F26: =F16+(F13* SUM(F18:F20))+SUM(F21:$J23) -> 71.2446 | G26: =G16+(G13* SUM(G18:G20))+SUM(G21:$J23) -> 71.2446 | H26: =H16+(H13* SUM(H18:H20))+SUM(H21:$J23) -> 91.184681 | I26: =I25 -> #REF! | J26: =J25 -> #REF! | K26: =K25 -> #REF!
C28: Unadjusted EPS | D28: =D14/D25*1000 -> 4264.8261 | E28: =E14/E25*1000 -> 605.36847 | F28: =F14/F25*1000 -> 1298.856 | G28: =G14/G25*1000 -> 900.79737 | H28: =H14/H25*1000 -> 1260.1845 | I28: =I14/I25*1000 -> #REF! | J28: =J14/J25*1000 -> #REF! | K28: =K14/K25*1000 -> #REF!
C29: Adjusted EPS | D29: =D14/D26*1000 -> 1451.235 | E29: =E14/E26*1000 -> 312.47616 | F29: =F14/F26*1000 -> 765.69945 | G29: =G14/G26*1000 -> 663.79069 | H29: =H14/H26*1000 -> 1037.0585 | I29: =I14/I26*1000 -> #REF! | J29: =J14/J26*1000 -> #REF! | K29: =K14/K26*1000 -> #REF! | M29: Going forward, C200 requires adjustment for employee bonus, we will start applying this treatment now
C31: EPS growth | E31: =E28/D28-1 -> -0.85805553 | F31: =F28/E28-1 -> 1.1455627 | G31: =G28/F28-1 -> -0.30646862 | H31: =H28/G28-1 -> 0.3989656 | I31: =I28/H28-1 -> #REF! | J31: =J28/I28-1 -> #REF! | K31: =K28/J28-1 -> #REF!
C32: Adj EPS growth | E32: =E29/D29-1 -> -0.78468259 | F32: =F29/E29-1 -> 1.4504252 | G32: =G29/F29-1 -> -0.13309239 | H32: =H29/G29-1 -> 0.56232754 | I32: =I29/H29-1 -> #REF! | J32: =J29/I29-1 -> #REF! | K32: =K29/J29-1 -> #REF!
C33: NPAT growth | E33: =E14/D14-1 -> -0.71611106 | F33: =F14/E14-1 -> 1.8882574 | G33: =G14/F14-1 -> -0.13309239 | H33: =H14/G14-1 -> 0.9995949 | I33: =I14/H14-1 -> -0.99738484 | J33: =J14/I14-1 -> 0.69265038 | K33: =K14/J14-1 -> 0.53448144
C35: P/E | E35: =$D$7/E29 -> #REF! | F35: =$D$7/F29 -> #REF! | G35: =D6/G29 -> #REF! | H35: =D6/H29 -> #REF! | I35: =D6/I29 -> #REF! | J35: =D7/J29 -> #REF! | K35: =$D$7/K29 -> #REF!
C37: Total Equity | D37: 288.99152 | E37: 457.17548 | F37: 579.59414 | G37: 663.61479 | H37: =#REF! -> #REF! | I37: =#REF! -> #REF! | J37: =#REF! -> #REF! | K37: =#REF! -> #REF!
C38: Minority interest | D38: 45.393554 | E38: 55.78551 | F38: 23.858045 | G38: 30.481793 | H38: =#REF! -> #REF! | I38: =#REF! -> #REF! | J38: =#REF! -> #REF! | K38: =#REF! -> #REF!
C39: Book value per share | D39: =(D37-D38)/D26*10^3 -> 5313.5586 | E39: =(E37-E38)/E26*10^3 -> 6640.6257 | F39: =(F37-F38)/F26*10^3 -> 7800.3961 | G39: =(G37-G38)/G26*10^3 -> 8886.7506 | H39: =(H37-H38)/H26*10^3 -> #REF! | I39: =(I37-I38)/I26*10^3 -> #REF! | J39: =(J37-J38)/J26*10^3 -> #REF! | K39: =(K37-K38)/K26*10^3 -> #REF!
C40: P/B | D40: =$D$6/D39 -> #REF! | E40: =$D$6/E39 -> #REF! | F40: =$D$6/F39 -> #REF! | G40: =$D$6/G39 -> #REF! | H40: =$D$6/H39 -> #REF! | I40: =$D$6/I39 -> #REF! | J40: =$D$7/J39 -> #REF! | K40: =$D$7/K39 -> #REF!
C42: NPAT less MI, reported | D42: ='P&L'!C30 -> 72.079287 | E42: ='P&L'!D30 -> 24.591496 | F42: ='P&L'!E30 -> 57.859951 | G42: ='P&L'!F30 -> 82.763994 | H42: ='P&L'!G30 -> 167.83449 | I42: ='P&L'!H30 -> 0.337 | J42: ='P&L'!I30 -> 0.50305051 | K42: ='P&L'!J30 -> 0.73327004
C43: Adjusted share count (basic)
C44: EPS basic reported | D44: =D42/D26*1000 -> 1572.2525 | E44: =E42/E26*1000 -> 406.84356 | F44: =F42/F26*1000 -> 812.13104 | G44: =G42/G26*1000 -> 1161.688 | H44: =H42/H26*1000 -> 1840.5996 | I44: =I42/I26*1000 -> #REF! | J44: =J42/J26*1000 -> #REF! | K44: =K42/K26*1000 -> #REF!
C45: EPS basic adjusted | D45: =D29 -> 1451.235 | E45: =E29 -> 312.47616 | F45: =F29 -> 765.69945 | G45: =G29 -> 663.79069 | H45: =H29 -> 1037.0585 | I45: =I29 -> #REF! | J45: =J29 -> #REF! | K45: =K29 -> #REF!
C46: Fully diluted shares | D46: =D26+10.56 -> 56.4046 | E46: =E26+10.56 -> 71.0046 | F46: =F26+10.56 -> 81.8046 | G46: =G26+10.56 -> 81.8046 | H46: =H26+10.56 -> 101.74468 | I46: =I26 -> #REF! | J46: =J26 -> #REF! | K46: =K26 -> #REF!
C47: EPS fully diluted | D47: =D14/D46*1000 -> 1179.5365 | E47: =E14/E46*1000 -> 266.00384 | F47: =F14/F46*1000 -> 666.85677 | G47: =G14/G46*1000 -> 578.10321 | H47: =H14/H46*1000 -> 929.42299 | I47: =I14/I46*1000 -> #REF! | J47: =J14/J46*1000 -> #REF! | K47: =K14/K46*1000 -> #REF!

Sheet Bloomberg
A3: =ticker -> DXG VN EQUITY | B3: ="CY"&year-12 -> CY2013
A4: Date | B4: =_xll.BDH($A$3,$A$5:$A$64,B3,"","Dir=H","Dts=S","Sort=A","Quote=C","QtTyp=Y","Days=A","Per=cy","DtFmt=D","Fill=0","UseDPDF=Y","cols=12;rows=61") -> #NAME? | C4: 37986 | D4: 38352 | E4: 38716 | F4: 39080 | G4: 39444 | H4: 39813 | I4: 40178 | J4: 40543 | K4: 40907 | L4: 41274 | M4: 41639 | N4: 42004
A5: SALES_REV_TURN | B5: 0 | C5: 0 | D5: 0 | E5: 0 | F5: 0 | G5: 28607.371 | H5: 28610.677 | I5: 84909.411 | J5: 374255.04 | K5: 286386.26 | L5: 403502.98 | M5: 342591.14 | N5: 506180.66
A6: IS_COGS_TO_FE_AND_PP_AND_G | B6: 0 | C6: 0 | D6: 0 | E6: 0 | F6: 0 | G6: 3518.2214 | H6: 4046.6697 | I6: 6118.7114 | J6: 204977.95 | K6: 80303.295 | L6: 210618.2 | M6: 136660.21 | N6: 204365.45
A7: ARD_SALES_MKT_ADVERTISING_EXP | B7: 0 | C7: 0 | D7: 0 | E7: 0 | F7: 0 | G7: 5283.724 | H7: 7905.5888 | I7: 18678.028 | J7: 35836.083 | K7: 45220.325 | L7: 44045.725 | M7: 62493.81 | N7: 54302.47 | P7: =L7+L8 -> 122716.96 | Q7: =M7+M8 -> 143739.85 | R7: =N7+N8 -> 136630.05
A8: ARD_GENERAL_ADMINISTRATIVE_EXP | B8: 0 | C8: 0 | D8: 0 | E8: 0 | F8: 0 | G8: 4482.1224 | H8: 8711.7508 | I8: 23742.199 | J8: 54237.319 | K8: 83735.938 | L8: 78671.24 | M8: 81246.045 | N8: 82327.577
A9: IS_OPER_INC | B9: 0 | C9: 0 | D9: 0 | E9: 0 | F9: 0 | G9: 15323.304 | H9: 7946.6674 | I9: 36370.473 | J9: 79203.69 | K9: 77126.706 | L9: 70167.824 | M9: 62191.073 | N9: 165185.16
A10: IS_FOREIGN_EXCH_LOSS | B10: 0 | C10: 0 | D10: 0 | E10: 0 | F10: 0 | G10: 0 | H10: 0 | I10: 0 | J10: 0 | K10: 0 | L10: -42.025 | M10: 0 | N10: 0
A11: IS_NET_NON_OPER_LOSS | B11: 0 | C11: 0 | D11: 0 | E11: 0 | F11: 0 | G11: -238.6071 | H11: -1524.915 | I11: -10921.238 | J11: -32021.182 | K11: -16821.034 | L11: -15520.407 | M11: -58637.8 | N11: -101263.15
A12: IS_INT_EXPENSE | B12: 0 | C12: 0 | D12: 0 | E12: 0 | F12: 0 | G12: 56.1367 | H12: 0 | I12: 5.3629 | J12: 1033.1689 | K12: 38554.054 | L12: 6616.4557 | M12: 342.829 | N12: 79.2907
A13: IS_INC_TAX_EXP | B13: 0 | C13: 0 | D13: 0 | E13: 0 | F13: 0 | G13: 4341.6167 | H13: 2638.9703 | I13: 9269.2797 | J13: 32336.92 | K13: 22333.479 | L13: 20018.952 | M13: 30756.144 | N13: 53321.005
A14: MIN_NONCONTROL_INTEREST_CREDITS | B14: 0 | C14: 0 | D14: 0 | E14: 0 | F14: 0 | G14: 0 | H14: 0 | I14: -124.1939 | J14: 5775.4965 | K14: 8468.7108 | L14: 1234.897 | M14: 6965.9064 | N14: 45213.531
A15: EBITDA | B15: 0 | C15: 0 | D15: 0 | E15: 0 | F15: 0 | G15: 15479.646 | H15: 8384.3383 | I15: 37359.175 | J15: 81273.525 | K15: 80987.137 | L15: 74063.457 | M15: 65730.594 | N15: 168474.61
A16: IS_DEPR_EXP | B16: 0 | C16: 0 | D16: 0 | E16: 0 | F16: 0 | G16: 156.3425 | H16: 437.671 | I16: 916.076 | J16: 1995.131 | K16: 2917.0359 | L16: 2959.1801 | M16: 2192.354 | N16: 2297.6035
A17: BS_CASH_NEAR_CASH_ITEM | B17: 0 | C17: 0 | D17: 0 | E17: 0 | F17: 0 | G17: 31559.074 | H17: 39657.925 | I17: 78033.22 | J17: 161564.46 | K17: 107361.8 | L17: 136052.65 | M17: 72886.29 | N17: 776338.99
A18: BS_MKT_SEC_OTHER_ST_INVEST | B18: 0 | C18: 0 | D18: 0 | E18: 0 | F18: 0 | G18: 0 | H18: 0 | I18: 0 | J18: 0 | K18: 0 | L18: 0 | M18: 0 | N18: 0
A19: BS_ACCT_NOTE_RCV | B19: 0 | C19: 0 | D19: 0 | E19: 0 | F19: 0 | G19: 0 | H19: 3332.833 | I19: 1684.5235 | J19: 51946.89 | K19: 137804.63 | L19: 125808.68 | M19: 131245.3 | N19: 119201.13
... A64: DVD_PAYOUT_RATIO | B64: 0 | C64: 0 | D64: 0 | E64: 0 | F64: 0 | G64: 0 | H64: 0 | I64: 73.4113 | J64: 59.2181 | K64: 0 | L64: 0 | M64: 0 | N64: 0
B66: ="CQ4"&year-3 -> CQ42022 | C66: ="CQ4"&year -> CQ42025
B67: =_xll.BDH(ticker,$A$68:$A$125,B66,C66,"Dir=H","Dts=S","Sort=A","Quote=C","QtTyp=Y","Days=A","Per=cq","DtFmt=D","Fill=0","UseDPDF=Y","cols=12;rows=59") -> #NAME? | C67: 40998 | D67: 41089 | E67: 41180 | F67: 41274 | G67: 41362 | H67: 41453 | I67: 41547 | J67: 41639 | K67: 41729 | L67: 41820 | M67: 41912 | N67: 42004 | O67: 42094
A68: SALES_REV_TURN | B68: 45976.524 | C68: 34725.55 | D68: 94877.759 | E68: 152942.42 | F68: 120957.26 | G68: 48773.071 | H68: 139055.14 | I68: 31324.253 | J68: 123438.67 | K68: 92389.558 | L68: 117633.06 | M68: 57464.837 | N68: 238693.2 | O68: 171599.67
A69: IS_COGS_TO_FE_AND_PP_AND_G | B69: 4822.3274 | C69: 3821.4099 | D69: 46378.936 | E69: 89321.595 | F69: 71096.255 | G69: 19581.237 | H69: 65363.035 | I69: 5599.4087 | J69: 46116.532 | K69: 42966.623 | L69: 34341.225 | M69: 20105.175 | N69: 106952.43 | O69: 71341.777
A70: ARD_SALES_MKT_ADVERTISING_EXP | B70: 15881.564 | C70: 6718.8995 | D70: 13199.601 | E70: 11821.989 | F70: 12305.236 | G70: 11643.514 | H70: 26212.991 | I70: 10077.196 | J70: 14560.108 | K70: 6828.6185 | L70: 12496.487 | M70: 10398.006 | N70: 24579.358 | O70: 14572.18
A71: ARD_GENERAL_ADMINISTRATIVE_EXP | B71: 29180.805 | C71: 19319.28 | D71: 19337.477 | E71: 18828.244 | F71: 21186.238 | G71: 17635.771 | H71: 18224.652 | I71: 20001.84 | J71: 25383.783 | K71: 15070.207 | L71: 19021.671 | M71: 17674.513 | N71: 30561.187 | O71: 24895.741
A72: IS_OPER_INC | B72: -3908.1724 | C72: 4865.9608 | D72: 15961.745 | E72: 32970.587 | F72: 16369.531 | G72: -87.4506 | H72: 29254.465 | I72: -4354.1914 | J72: 37378.25 | K72: 27524.11 | L72: 51773.681 | M72: 9287.1427 | N72: 76600.228 | O72: 60789.973
A73: IS_FOREIGN_EXCH_LOSS | B73: 0 | C73: 0 | D73: 0 | E73: 0 | F73: 0 | G73: 0 | H73: 0 | I73: 0 | J73: 0 | K73: 0 | L73: 0 | M73: 0 | N73: 0 | O73: 0
A74: IS_NET_NON_OPER_LOSS | B74: -1800.6132 | C74: -1554.492 | D74: 397.8238 | E74: -2357.5704 | F74: -12048.193 | G74: -1982.2024 | H74: -1484.1765 | I74: -43705.19 | J74: -11466.231 | K74: -1336.4533 | L74: -5666.0597 | M74: -5999.0715 | N74: -88261.57 | O74: -10696.592
A75: IS_INT_EXPENSE | B75: 14047.063 | C75: 3709.756 | D75: 1776.8341 | E75: 1073.3554 | F75: 56.5102 | G75: 45.5231 | H75: 55.1752 | I75: 32.2711 | J75: 209.8597 | K75: 33.6088 | L75: 11.0954 | M75: 9.8985 | N75: 24.6881 | O75: 25.3813
A76: IS_INC_TAX_EXP | B76: 1196.5996 | C76: 4032.2641 | D76: 4465.5487 | E76: 7039.2748 | F76: 4481.864 | G76: 1939.814 | H76: 10032.337 | I76: 9490.7923 | J76: 9293.2007 | K76: 6650.3025 | L76: 12662.513 | M76: 4485.0403 | N76: 29523.15 | O76: 12201.29
A77: MIN_NONCONTROL_INTEREST_CREDITS | B77: 413.2477 | C77: -3875.888 | D77: 3633.6453 | E77: 1722.1895 | F77: -245.0498 | G77: -1495.3463 | H77: 576.1958 | I77: -251.3511 | J77: 8136.408 | K77: 859.7138 | L77: 13436 | M77: 9823.3077 | N77: 21094.509 | O77: 22664.508
A78: EBITDA | B78: -3302.6433 | C78: 5825.668 | D78: 16666.082 | E78: 33755.945 | F78: 18034.842 | G78: 927.5444 | H78: 30202.27 | I78: -3472.8279 | J78: 38073.607 | K78: 28342.567 | L78: 52592.414 | M78: 10101.104 | N78: 77438.521 | O78: 61546.401
A79: IS_DEPR_EXP | B79: 597.1047 | C79: 725.5938 | D79: 689.3034 | E79: 770.3237 | F79: 773.9593 | G79: 780.5484 | H79: 713.3222 | I79: 648.1406 | J79: 50.3428 | K79: 577.3177 | L79: 577.593 | M79: 566.8921 | N79: 575.8007 | O79: 643.0904
... A125: PX LAST | B125: 5407.72 | C125: 6643.77 | D125: 7339.04 | E125: 5871.24 | F125: 8343.33 | G125: 8806.85 | H125: 9149.86 | I125: 8565.82 | J125: 12500 | K125: 16300 | L125: 12659.3 | M125: 13084.11 | N125: 11894.65 | O125: 15454.55

Sheet FS Year
C1: Currrent Price | D1: 15900
D2: ='Valuation summary'!P47 -> 14309.04 | L2: =32*1.25 -> 40 | M2: =42*1.25 -> 52.5 | N2: =52.8*1.25 -> 66 | O2: 75 | P2: 75 | Q2: 125 | R2: 125 | T2: 17400
L3: 25000 | M3: 58000 | N3: 83000 | P3: =135*1000 -> 135000 | Q3: =Q24*1000 -> 337 | R3: =R24*1000 -> 503.05051 | T3: =$T$2/M142 -> 1.6437658 | U3: =$T$2/N142 -> 1.8138369 | V3: =$T$2/P142 -> #DIV/0! | W3: =$T$2/Q142 -> #DIV/0! | X3: =$T$2/R142 -> #DIV/0!
L4: =L3/L2 -> 625 | M4: =M3/M2 -> 1104.7619 | N4: =N3/N2 -> 1257.5758 | P4: =P3/P2 -> 1800 | Q4: =Q3/Q2 -> 2.696 | R4: =R3/R2 -> 4.0244041
L5: =$D$1/L4 -> 25.44 | M5: =$D$1/M4 -> 14.392241 | N5: =$D$1/N4 -> 12.643373 | P5: =$D$2/P4 -> 7.9494667 | Q5: =$D$2/Q4 -> 5307.5074 | R5: =$D$2/R4 -> 3555.5674
N6: =(N4-M4)/M4 -> 0.13832288 | P6: =(P4-N4)/N4 -> 0.4313253 | Q6: =(Q4-P4)/P4 -> -0.99850222 | R6: =(R4-Q4)/Q4 -> 0.49273148
B7: =ticker -> DXG VN EQUITY | N7: 1.25 | R7: =((R4/P4)^(1/3))-1 -> -0.86923956
B8: 1000
B9: INCOME STATEMENT | D9: =year-12 -> 2013 | E9: =D9+1 -> 2014 | F9: =E9+1 -> 2015 | G9: =F9+1 -> 2016 | H9: =G9+1 -> 2017 | I9: =H9+1 -> 2018 | J9: =I9+1 -> 2019 | K9: =J9+1 -> 2020 | L9: =K9+1 -> 2021 | ... N9: =M9+1 -> 2023 | O9: 2014A | P9: =N9+1 -> 2024 | Q9: =P9+1 -> 2025 | R9: =Q9+1 -> 2026 | S9: =R9+1 -> 2027 | T9: =S9+1 -> 2028 | U9: =T9+1 -> 2029 | V9: =U9+1 -> 2030 | W9: =V9+1 -> 2031 | X9: =W9+1 -> 2032 | Y9: =X9+1 -> 2033
B10: Revenue | D10: =Bloomberg!C5/unit -> 0 | E10: =Bloomberg!D5/unit -> 0 | F10: =Bloomberg!E5/unit -> 0 | G10: =Bloomberg!F5/unit -> 0 | H10: =Bloomberg!G5/unit -> 28.607371 | I10: =Bloomberg!H5/unit -> 28.610677 | J10: =Bloomberg!I5/unit -> 84.909411 | K10: =Bloomberg!J5/unit -> 374.25504 | ... O10: =Bloomberg!N5/unit -> 506.18066 | P10: ='P&L'!#REF! -> #REF! | Q10: ='P&L'!H10 -> 1.395 | R10: ='P&L'!I10 -> 2.5065169 | S10: ='P&L'!J10 -> 2.8792414 | T10: ='P&L'!K10 -> 4.6453186 | U10: ='P&L'!L10 -> 5.8135777 | V10: ='P&L'!M10 -> 0 | W10: ='P&L'!N10 -> 0 | X10: ='P&L'!O10 -> 0 | Y10: ='P&L'!P10 -> 0
B11: - Cost of goods sold | D11: =-Bloomberg!C6/unit -> 0 | E11: =-Bloomberg!D6/unit -> 0 | F11: =-Bloomberg!E6/unit -> 0 | G11: =-Bloomberg!F6/unit -> 0 | H11: =-Bloomberg!G6/unit -> -3.5182214 | I11: =-Bloomberg!H6/unit -> -4.0466697 | J11: =-Bloomberg!I6/unit -> -6.1187114 | K11: =-Bloomberg!J6/unit -> -204.97795 | ... O11: =-Bloomberg!N6/unit -> -204.36545 | P11: ='P&L'!#REF! -> #REF! | Q11: ='P&L'!H11 -> -0.735 | R11: ='P&L'!I11 -> -1.4548796 | S11: ='P&L'!J11 -> -1.14944 | T11: ='P&L'!K11 -> -2.0305444 | U11: ='P&L'!L11 -> -2.7299755 | V11: ='P&L'!M11 -> 0 | W11: ='P&L'!N11 -> 0 | X11: ='P&L'!O11 -> 0 | Y11: ='P&L'!P11 -> 0
B12: Gross profit | D12: =SUM(D10:D11) -> 0 | E12: =SUM(E10:E11) -> 0 | F12: =SUM(F10:F11) -> 0 | G12: =SUM(G10:G11) -> 0 | H12: =SUM(H10:H11) -> 25.08915 | I12: =SUM(I10:I11) -> 24.564007 | J12: =SUM(J10:J11) -> 78.790699 | K12: =SUM(K10:K11) -> 169.27709 | ... O12: =SUM(O10:O11) -> 301.81521 | P12: ='P&L'!#REF! -> #REF! | Q12: ='P&L'!H12 -> 0.66 | R12: ='P&L'!I12 -> 1.0516373 | S12: ='P&L'!J12 -> 1.7298014 | T12: ='P&L'!K12 -> 2.6147742 | U12: ='P&L'!L12 -> 3.0836022 | V12: ='P&L'!M12 -> 0 | W12: ='P&L'!N12 -> 0 | X12: ='P&L'!O12 -> 0 | Y12: ='P&L'!P12 -> 0
B13: - Sales and marketing exp | D13: =-Bloomberg!C7/unit -> 0 | E13: =-Bloomberg!D7/unit -> 0 | F13: =-Bloomberg!E7/unit -> 0 | G13: =-Bloomberg!F7/unit -> 0 | H13: =-Bloomberg!G7/unit -> -5.283724 | I13: =-Bloomberg!H7/unit -> -7.9055888 | J13: =-Bloomberg!I7/unit -> -18.678028 | K13: =-Bloomberg!J7/unit -> -35.836083 | ... O13: =-Bloomberg!N7/unit -> -54.30247 | P13: ='P&L'!#REF! -> #REF! | Q13: ='P&L'!H14 -> -0.162 | R13: ='P&L'!I14 -> -0.25330222 | S13: ='P&L'!J14 -> -0.34785493 | T13: ='P&L'!K14 -> -0.5146234 | U13: ='P&L'!L14 -> -0.66952142 | V13: ='P&L'!M14 -> 0 | W13: ='P&L'!N14 -> 0 | X13: ='P&L'!O14 -> 0 | Y13: ='P&L'!P14 -> 0
B14: - General and administrative exp | D14: =-Bloomberg!C8/unit -> 0 | E14: =-Bloomberg!D8/unit -> 0 | F14: =-Bloomberg!E8/unit -> 0 | G14: =-Bloomberg!F8/unit -> 0 | H14: =-Bloomberg!G8/unit -> -4.4821224 | I14: =-Bloomberg!H8/unit -> -8.7117508 | J14: =-Bloomberg!I8/unit -> -23.742199 | K14: =-Bloomberg!J8/unit -> -54.237319 | ... O14: =-Bloomberg!N8/unit -> -82.327577 | P14: ='P&L'!#REF! -> #REF! | Q14: ='P&L'!H16 -> -0.108 | R14: ='P&L'!I16 -> -0.15524975 | S14: ='P&L'!J16 -> -0.1956684 | T14: ='P&L'!K16 -> -0.26510903 | U14: ='P&L'!L16 -> -0.3150689 | V14: ='P&L'!M16 -> 0 | W14: ='P&L'!N16 -> 0 | X14: ='P&L'!O16 -> 0 | Y14: ='P&L'!P16 -> 0
B15: Operating profit | D15: =SUM(D12:D14) -> 0 | E15: =SUM(E12:E14) -> 0 | F15: =SUM(F12:F14) -> 0 | G15: =SUM(G12:G14) -> 0 | H15: =SUM(H12:H14) -> 15.323303 | I15: =SUM(I12:I14) -> 7.9466674 | J15: =SUM(J12:J14) -> 36.370473 | K15: =SUM(K12:K14) -> 79.20369 | ... O15: =SUM(O12:O14) -> 165.18516 | P15: =P12+P13+P14 -> #REF! | Q15: =Q12+Q13+Q14 -> 0.39 | R15: =R12+R13+R14 -> 0.6430853 | S15: =S12+S13+S14 -> 1.186278 | T15: =T12+T13+T14 -> 1.8350418 | U15: =U12+U13+U14 -> 2.0990119 | V15: =V12+V13+V14 -> 0 | W15: =W12+W13+W14 -> 0 | ... Y15: =Y12+Y13+Y14 -> 0
B16: - Forex (losses) / gains | D16: =-Bloomberg!C10/unit -> 0 | E16: =-Bloomberg!D10/unit -> 0 | F16: =-Bloomberg!E10/unit -> 0 | G16: =-Bloomberg!F10/unit -> 0 | H16: =-Bloomberg!G10/unit -> 0 | I16: =-Bloomberg!H10/unit -> 0 | J16: =-Bloomberg!I10/unit -> 0 | K16: =-Bloomberg!J10/unit -> 0 | ... O16: =-Bloomberg!N10/unit -> 0 | P16: ='P&L'!#REF! -> #REF! | Q16: ='P&L'!H21 -> 0.093 | R16: ='P&L'!I21 -> 0.10465975 | S16: ='P&L'!J21 -> 0.066074832 | T16: ='P&L'!K21 -> 0.20673132 | U16: ='P&L'!L21 -> 0.27047204 | V16: ='P&L'!M21 -> 0 | W16: ='P&L'!N21 -> 0 | X16: ='P&L'!O21 -> 0 | Y16: ='P&L'!P21 -> 0
B17: - Net non-operating (losses) / gains | D17: =-Bloomberg!C11/unit -> 0 | E17: =-Bloomberg!D11/unit -> 0 | F17: =-Bloomberg!E11/unit -> 0 | G17: =-Bloomberg!F11/unit -> 0 | H17: =-Bloomberg!G11/unit -> 0.2386071 | I17: =-Bloomberg!H11/unit -> 1.524915 | J17: =-Bloomberg!I11/unit -> 10.921238 | K17: =-Bloomberg!J11/unit -> 32.021182 | ... O17: =-Bloomberg!N11/unit -> 101.26315 | P17: ='P&L'!#REF! -> #REF! | Q17: ='P&L'!H22+'P&L'!H24+'P&L'!H25 -> 0.123 | R17: ='P&L'!I22+'P&L'!I24+'P&L'!I25 -> 0.10619569 | S17: ='P&L'!J22+'P&L'!J24+'P&L'!J25 -> 0.14563212 | T17: ='P&L'!K22+'P&L'!K24+'P&L'!K25 -> 0.25076595 | U17: ='P&L'!L22+'P&L'!L24+'P&L'!L25 -> 0.22806085 | V17: ='P&L'!M22+'P&L'!M24+'P&L'!M25 -> 0 | W17: ='P&L'!N22+'P&L'!N24+'P&L'!N25 -> 0 | X17: ='P&L'!O22+'P&L'!O24+'P&L'!O25 -> 0 | Y17: ='P&L'!P22+'P&L'!P24+'P&L'!P25 -> 0
B18: EBIT | D18: =SUM(D15:D17) -> 0 | E18: =SUM(E15:E17) -> 0 | F18: =SUM(F15:F17) -> 0 | G18: =SUM(G15:G17) -> 0 | H18: =SUM(H15:H17) -> 15.56191 | I18: =SUM(I15:I17) -> 9.4715824 | J18: =SUM(J15:J17) -> 47.291711 | K18: =SUM(K15:K17) -> 111.22487 | ... Y18: =SUM(Y15:Y17) -> 0
B19: - Interest exp | D19: =-Bloomberg!C12/unit -> 0 | E19: =-Bloomberg!D12/unit -> 0 | F19: =-Bloomberg!E12/unit -> 0 | G19: =-Bloomberg!F12/unit -> 0 | H19: =-Bloomberg!G12/unit -> -0.0561367 | I19: =-Bloomberg!H12/unit -> 0 | J19: =-Bloomberg!I12/unit -> -0.0053629 | K19: =-Bloomberg!J12/unit -> -1.0331689 | ... O19: =-Bloomberg!N12/unit -> -0.0792907 | P19: ='P&L'!#REF! -> #REF! | Q19: ='P&L'!H23 -> -0.009 | R19: ='P&L'!I23 -> -0.032702591 | S19: ='P&L'!J23 -> -0.062664889 | T19: ='P&L'!K23 -> -0.19075452 | U19: ='P&L'!L23 -> -0.20903103 | V19: ='P&L'!M23 -> 0 | W19: ='P&L'!N23 -> 0 | X19: ='P&L'!O23 -> 0 | Y19: ='P&L'!P23 -> 0
B20: EBT | D20: =SUM(D18:D19) -> 0 | E20: =SUM(E18:E19) -> 0 | F20: =SUM(F18:F19) -> 0 | G20: =SUM(G18:G19) -> 0 | H20: =SUM(H18:H19) -> 15.505774 | I20: =SUM(I18:I19) -> 9.4715824 | J20: =SUM(J18:J19) -> 47.286348 | K20: =SUM(K18:K19) -> 110.1917 | ... O20: =SUM(O18:O19) -> 266.36903 | P20: ='P&L'!#REF! -> #REF! | Q20: =SUM(Q18:Q19) -> 0.597 | R20: =SUM(R18:R19) -> 0.82123814 | S20: =SUM(S18:S19) -> 1.3353201 | T20: =SUM(T18:T19) -> 2.1017845 | U20: =SUM(U18:U19) -> 2.3885138 | V20: =SUM(V18:V19) -> 0 | W20: =SUM(W18:W19) -> 0 | X20: =SUM(X18:X19) -> 0 | Y20: =SUM(Y18:Y19) -> 0
B21: - Income tax exp | D21: =-Bloomberg!C13/unit -> 0 | E21: =-Bloomberg!D13/unit -> 0 | F21: =-Bloomberg!E13/unit -> 0 | G21: =-Bloomberg!F13/unit -> 0 | H21: =-Bloomberg!G13/unit -> -4.3416167 | I21: =-Bloomberg!H13/unit -> -2.6389703 | J21: =-Bloomberg!I13/unit -> -9.2692797 | K21: =-Bloomberg!J13/unit -> -32.33692 | ... O21: =-Bloomberg!N13/unit -> -53.321005 | P21: ='P&L'!#REF! -> #REF! | Q21: ='P&L'!H27 -> -0.095 | R21: ='P&L'!I27 -> -0.15681483 | S21: ='P&L'!J27 -> -0.24989984 | T21: ='P&L'!K27 -> -0.37898975 | U21: ='P&L'!L27 -> -0.5022951 | V21: ='P&L'!M27 -> 0 | W21: ='P&L'!N27 -> 0 | X21: ='P&L'!O27 -> 0 | Y21: ='P&L'!P27 -> 0
B22: Profit after tax | D22: =SUM(D20:D21) -> 0 | E22: =SUM(E20:E21) -> 0 | F22: =SUM(F20:F21) -> 0 | G22: =SUM(G20:G21) -> 0 | H22: =SUM(H20:H21) -> 11.164157 | I22: =SUM(I20:I21) -> 6.8326121 | J22: =SUM(J20:J21) -> 38.017069 | K22: =SUM(K20:K21) -> 77.854783 | ... O22: =SUM(O20:O21) -> 213.04802 | P22: ='P&L'!#REF! -> #REF! | Q22: ='P&L'!H28 -> 0.446 | R22: ='P&L'!I28 -> 0.63027029 | S22: ='P&L'!J28 -> 1.0677995 | T22: ='P&L'!K28 -> 1.7282958 | U22: ='P&L'!L28 -> 1.8074943 | V22: ='P&L'!M28 -> 0 | W22: ='P&L'!N28 -> 0 | X22: ='P&L'!O28 -> 0 | Y22: ='P&L'!P28 -> 0
B23: - Minority interests | D23: =-Bloomberg!C14/unit -> 0 | E23: =-Bloomberg!D14/unit -> 0 | F23: =-Bloomberg!E14/unit -> 0 | G23: =-Bloomberg!F14/unit -> 0 | H23: =-Bloomberg!G14/unit -> 0 | I23: =-Bloomberg!H14/unit -> 0 | J23: =-Bloomberg!I14/unit -> 0.1241939 | K23: =-Bloomberg!J14/unit -> -5.7754965 | ... O23: =-Bloomberg!N14/unit -> -45.213531 | P23: ='P&L'!#REF! -> #REF! | Q23: ='P&L'!H29 -> -0.109 | R23: ='P&L'!I29 -> -0.12721978 | S23: ='P&L'!J29 -> -0.33452951 | T23: ='P&L'!K29 -> -0.54436776 | U23: ='P&L'!L29 -> -0.6697039 | V23: ='P&L'!M29 -> 0 | W23: ='P&L'!N29 -> 0 | X23: ='P&L'!O29 -> 0 | Y23: ='P&L'!P29 -> 0
B24: Net income to shareholders | D24: =SUM(D22:D23) -> 0 | E24: =SUM(E22:E23) -> 0 | F24: =SUM(F22:F23) -> 0 | G24: =SUM(G22:G23) -> 0 | H24: =SUM(H22:H23) -> 11.164157 | I24: =SUM(I22:I23) -> 6.8326121 | J24: =SUM(J22:J23) -> 38.141262 | K24: =SUM(K22:K23) -> 72.079287 | ... O24: =SUM(O22:O23) -> 167.83449 | P24: ='P&L'!#REF! -> #REF! | Q24: ='P&L'!H30 -> 0.337 | R24: ='P&L'!I30 -> 0.50305051 | S24: ='P&L'!J30 -> 0.73327004 | T24: ='P&L'!K30 -> 1.183928 | U24: ='P&L'!L30 -> 1.1377904 | V24: ='P&L'!M30 -> 0 | W24: ='P&L'!N30 -> 0 | X24: ='P&L'!O30 -> 0 | Y24: ='P&L'!P30 -> 0
B25: Earnings per share (basic) | D25: =D24/D29*10^3 -> #DIV/0! | E25: =E24/E29*10^3 -> #DIV/0! | F25: =F24/F29*10^3 -> #DIV/0! | G25: =G24/G29*10^3 -> #DIV/0! | H25: =H24/H29*10^3 -> 14885.543 | I25: =I24/I29*10^3 -> 1438.4447 | J25: =J24/J29*10^3 -> 4767.6578 | K25: =K24/K29*10^3 -> 6006.6072 | ... Y25: =Y24/Y29*10^3 -> #REF!
B26: Earnings per share (adjusted) | K26: =K24/K30*10^3 -> 6006.6072 | L26: =L24/L30*10^3 -> 1024.6457 | M26: =M24/M30*10^3 -> 1377.6179 | N26: =N24/N30*10^3 -> 1567.5093 | O26: =O24/O30*10^3 -> 2237.7932 | P26: =P4 -> 1800 | Q26: =Q4 -> 2.696 | R26: =R24/R30*10^3 -> #REF! | S26: =S24/S30*10^3 -> #REF!
B27: EBITDA | D27: =D18-D28 -> 0 | E27: =E18-E28 -> 0 | F27: =F18-F28 -> 0 | G27: =G18-G28 -> 0 | H27: =H18-H28 -> 15.718253 | I27: =I18-I28 -> 9.9092534 | J27: =J18-J28 -> 48.207787 | K27: =K18-K28 -> 113.22 | ... O27: =O18-O28 -> 268.74592 | P27: ='P&L'!#REF! -> #REF! | Q27: ='P&L'!H33 -> 0.3953 | R27: ='P&L'!I33 -> 0.6469853 | S27: ='P&L'!J33 -> 1.191123 | T27: ='P&L'!K33 -> 1.8408318 | U27: ='P&L'!L33 -> 2.1057469 | V27: ='P&L'!M33 -> 0 | W27: ='P&L'!N33 -> #REF! | X27: ='P&L'!O33 -> #REF! | Y27: ='P&L'!P33 -> #REF!
B28: Depreciation expense | D28: =-Bloomberg!C16/unit -> 0 | E28: =-Bloomberg!D16/unit -> 0 | F28: =-Bloomberg!E16/unit -> 0 | G28: =-Bloomberg!F16/unit -> 0 | H28: =-Bloomberg!G16/unit -> -0.1563425 | I28: =-Bloomberg!H16/unit -> -0.437671 | J28: =-Bloomberg!I16/unit -> -0.916076 | K28: =-Bloomberg!J16/unit -> -1.995131 | ... O28: =-Bloomberg!N16/unit -> -2.2976035 | P28: ='P&L'!#REF! -> #REF! | Q28: ='P&L'!H34 -> -0.0053 | R28: ='P&L'!I34 -> -0.0039 | S28: ='P&L'!J34 -> -0.004845 | T28: ='P&L'!K34 -> -0.00579 | U28: ='P&L'!L34 -> -0.006735 | V28: ='P&L'!M34 -> 0 | W28: ='P&L'!N34 -> #REF! | X28: ='P&L'!O34 -> #REF! | Y28: ='P&L'!P34 -> #REF!
B29: Outstanding shares | D29: =(C58+D58)/2/10 -> 0 | E29: =(D58+E58)/2/10 -> 0 | F29: =(E58+F58)/2/10 -> 0 | G29: =(F58+G58)/2/10 -> 0 | H29: =(G58+H58)/2/10 -> 0.75 | I29: =(H58+I58)/2/10 -> 4.75 | J29: =(I58+J58)/2/10 -> 8 | K29: =(J58+K58)/2/10 -> 12 | L29: =((K58+L58)/2/10)*1.25 -> 30 | M29: =((L58+M58)/2/10)*1.25 -> 46.25 | N29: =((M58+N58)/2/10)*1.25 -> 59.249801 | O29: =((N58+O58)/2/10)*1.25 -> 79.874801 | P29: =(N58+P58)/2/10 -> #REF! | Q29: =(O58+Q58)/2/10 -> #REF! | R29: =(Q58+R58)/2/10 -> #REF! | S29: =(R58+S58)/2/10 -> #REF! | T29: =(S58+T58)/2/10 -> #REF! | U29: =(T58+U58)/2/10 -> #REF! | V29: =(U58+V58)/2/10 -> #REF! | W29: =(V58+W58)/2/10 -> #REF! | X29: =(W58+X58)/2/10 -> #REF! | Y29: =(X58+Y58)/2/10 -> #REF!
B30: Outstanding shares (adjusted) | K30: 12 | L30: 24 | M30: =M58/10 -> 42 | N30: =N58/10 -> 52.799681 | O30: =O58/10 -> 75 | P30: =P58/10 -> #REF! | Q30: =Q58/10 -> #REF! | R30: =R58/10 -> #REF! | S30: =S58/10 -> #REF! | T30: =T58/10 -> #REF! | ... V30: =V58/10 -> #REF! | W30: =V30 -> #REF! | X30: =W30 -> #REF! | Y30: =X30 -> #REF!
B31: BALANCE SHEET
B32: Assets
B33: + Cash & equivalents | D33: =Bloomberg!C17/unit -> 0 | E33: =Bloomberg!D17/unit -> 0 | F33: =Bloomberg!E17/unit -> 0 | G33: =Bloomberg!F17/unit -> 0 | H33: =Bloomberg!G17/unit -> 31.559074 | I33: =Bloomberg!H17/unit -> 39.657925 | J33: =Bloomberg!I17/unit -> 78.03322 | K33: =Bloomberg!J17/unit -> 161.56446 | ... O33: =Bloomberg!N17/unit -> 776.33899 | P33: =#REF! -> #REF! | Q33: =#REF! -> #REF! | R33: =#REF! -> #REF! | S33: =#REF! -> #REF! | T33: =#REF! -> #REF! | U33: =#REF! -> #REF! | V33: =#REF! -> #REF! | W33: =#REF! -> #REF! | ... Y33: =#REF! -> #REF!
B34: + Short-term investments | D34: =Bloomberg!C18/unit -> 0 | E34: =Bloomberg!D18/unit -> 0 | F34: =Bloomberg!E18/unit -> 0 | G34: =Bloomberg!F18/unit -> 0 | H34: =Bloomberg!G18/unit -> 0 | I34: =Bloomberg!H18/unit -> 0 | J34: =Bloomberg!I18/unit -> 0 | K34: =Bloomberg!J18/unit -> 0 | ... O34: =Bloomberg!N18/unit -> 0 | P34: =#REF! -> #REF! | Q34: =#REF! -> #REF! | R34: =#REF! -> #REF! | S34: =#REF! -> #REF! | T34: =#REF! -> #REF! | U34: =#REF! -> #REF! | V34: =#REF! -> #REF! | W34: =#REF! -> #REF! | ... Y34: =#REF! -> #REF!
B35: + Accounts & notes receivables | D35: =Bloomberg!C19/unit -> 0 | E35: =Bloomberg!D19/unit -> 0 | F35: =Bloomberg!E19/unit -> 0 | G35: =Bloomberg!F19/unit -> 0 | H35: =Bloomberg!G19/unit -> 0 | I35: =Bloomberg!H19/unit -> 3.332833 | J35: =Bloomberg!I19/unit -> 1.6845235 | K35: =Bloomberg!J19/unit -> 51.94689 | ... O35: =Bloomberg!N19/unit -> 119.20113 | P35: =#REF! -> #REF! | Q35: =#REF! -> #REF! | R35: =#REF! -> #REF! | S35: =#REF! -> #REF! | T35: =#REF! -> #REF! | U35: =#REF! -> #REF! | V35: =#REF! -> #REF! | W35: =#REF! -> #REF! | ... Y35: =#REF! -> #REF!
B36: + Inventories | D36: =Bloomberg!C20/unit -> 0 | E36: =Bloomberg!D20/unit -> 0 | F36: =Bloomberg!E20/unit -> 0 | G36: =Bloomberg!F20/unit -> 0 | H36: =Bloomberg!G20/unit -> 11.029091 | I36: =Bloomberg!H20/unit -> 47.387504 | J36: =Bloomberg!I20/unit -> 167.4791 | K36: =Bloomberg!J20/unit -> 249.43949 | ... O36: =Bloomberg!N20/unit -> 499.21431 | P36: =#REF! -> #REF! | Q36: =#REF! -> #REF! | R36: =#REF! -> #REF! | S36: =#REF! -> #REF! | T36: =#REF! -> #REF! | U36: =#REF! -> #REF! | V36: =#REF! -> #REF! | W36: =#REF! -> #REF! | ... Y36: =#REF! -> #REF!
B37: + Other current assets | D37: =Bloomberg!C21/unit -> 0 | E37: =Bloomberg!D21/unit -> 0 | F37: =Bloomberg!E21/unit -> 0 | G37: =Bloomberg!F21/unit -> 0 | H37: =Bloomberg!G21/unit -> 19.645768 | I37: =Bloomberg!H21/unit -> 178.41997 | J37: =Bloomberg!I21/unit -> 205.53053 | K37: =Bloomberg!J21/unit -> 77.914041 | ... O37: =Bloomberg!N21/unit -> 284.11639 | P37: =#REF! -> #REF! | Q37: =#REF! -> #REF! | R37: =#REF! -> #REF! | S37: =#REF! -> #REF! | T37: =#REF! -> #REF! | U37: =#REF! -> #REF! | V37: =#REF! -> #REF! | W37: =#REF! -> #REF! | ... Y37: =#REF! -> #REF!
B38: Total current assets | D38: =Bloomberg!C22/unit -> 0 | E38: =Bloomberg!D22/unit -> 0 | F38: =Bloomberg!E22/unit -> 0 | G38: =Bloomberg!F22/unit -> 0 | H38: =Bloomberg!G22/unit -> 62.233934 | I38: =Bloomberg!H22/unit -> 268.79823 | J38: =Bloomberg!I22/unit -> 452.72738 | K38: =Bloomberg!J22/unit -> 540.86489 | ... O38: =Bloomberg!N22/unit -> 1678.8708 | P38: =#REF! -> #REF! | Q38: =#REF! -> #REF! | R38: =#REF! -> #REF! | S38: =#REF! -> #REF! | T38: =#REF! -> #REF! | U38: =#REF! -> #REF! | V38: =#REF! -> #REF! | W38: =#REF! -> #REF! | ... Y38: =#REF! -> #REF!
B39: + Gross fixed assets | D39: =Bloomberg!C23/unit -> 0 | E39: =Bloomberg!D23/unit -> 0 | F39: =Bloomberg!E23/unit -> 0 | G39: =Bloomberg!F23/unit -> 0 | H39: =Bloomberg!G23/unit -> 1.368667 | I39: =Bloomberg!H23/unit -> 2.9289248 | J39: =Bloomberg!I23/unit -> 11.021873 | K39: =Bloomberg!J23/unit -> 17.300869 | ... O39: =Bloomberg!N23/unit -> 42.124221 | P39: =#REF! -> #REF! | Q39: =#REF! -> #REF! | R39: =#REF! -> #REF! | S39: =#REF! -> #REF! | T39: =#REF! -> #REF! | U39: =#REF! -> #REF! | V39: =#REF! -> #REF! | W39: =#REF! -> #REF! | ... Y39: =#REF! -> #REF!
B40: - Accumulated depreciation | D40: =-Bloomberg!C24/unit -> 0 | E40: =-Bloomberg!D24/unit -> 0 | F40: =-Bloomberg!E24/unit -> 0 | G40: =-Bloomberg!F24/unit -> 0 | H40: =-Bloomberg!G24/unit -> -0.2351129 | I40: =-Bloomberg!H24/unit -> -0.6448353 | J40: =-Bloomberg!I24/unit -> -1.560911 | K40: =-Bloomberg!J24/unit -> -3.548641 | ... O40: =-Bloomberg!N24/unit -> -9.8412946 | P40: =#REF! -> #REF! | Q40: =#REF! -> #REF! | R40: =#REF! -> #REF! | S40: =#REF! -> #REF! | T40: =#REF! -> #REF! | U40: =#REF! -> #REF! | V40: =#REF! -> #REF! | W40: =#REF! -> #REF! | ... Y40: =#REF! -> #REF!
...

Sheet VCSC
C7: DXG | F7: Settings
C8: =C7&" VN EQUITY" -> DXG VN EQUITY | F8: English
C9: Ho Chi Minh | E9: =IF(F9="VND million",1,1000) -> 1000 | F9: VND Billion
A10: =IF(C9="Ho Chi Minh","VNIndex", "HNIndex") -> VNIndex | C10: =YEAR(TODAY()) -> 2025 | E10: VND | F10: 21000
A11: =year+9 -> 2034 | C11: =TODAY() -> 45874
C13: =IF(F16>VCSC!C64,VCSC!D64,IF(F16>VCSC!C65,VCSC!D65,IF(F16>VCSC!C66,VCSC!D66,IF(F16>VCSC!C67,VCSC!D67,"Sell")))) -> HOLD | J13: =VCSC!F8 -> English
J14: =IF($J$13="English",Y14,Z14) -> Income statement | K14: ='FS Year'!M9 -> 2022 | L14: ='FS Year'!N9 -> 2023 | M14: ='FS Year'!P9 -> 2024 | N14: ='FS Year'!Q9 -> 2025 | O14: ='FS Year'!R9 -> 2026 | Q14: =IF($J$13="english",AA14,AB14) -> Balance sheet | R14: =K14 -> 2022 | S14: =L14 -> 2023 | T14: =M14 -> 2024 | U14: =N14 -> 2025 | V14: =O14 -> 2026 | Y14: Income statement | Z14: CĐKT | AA14: Balance sheet | AB14: CĐKT
C15: Target price | F15: =ROUNDDOWN('Valuation summary'!T25/1000,1)*1000 -> #REF! | J15: =IF($J$13="english",Y15,Z15) -> Revenue | K15: ='FS Year'!M10 -> 403.50298 | L15: ='FS Year'!N10 -> 342.59114 | M15: ='FS Year'!O10 -> 506.18066 | N15: ='FS Year'!Q10 -> 1.395 | O15: ='FS Year'!R10 -> 2.5065169 | Q15: =IF($J$13="english",AA15,AB15) -> Assets | Y15: Revenue | Z15: Doanh thu thuần | AA15: Assets | AB15: Tài sản
C16: Upside/Downside | F16: =IFERROR(F15/F21-1,0)*100 -> 0 | J16: =IF($J$13="english",Y16,Z16) -> - Cost of goods sold | K16: ='FS Year'!M11 -> -210.6182 | L16: ='FS Year'!N11 -> -136.66021 | M16: ='FS Year'!O11 -> -204.36545 | N16: ='FS Year'!Q11 -> -0.735 | O16: ='FS Year'!R11 -> -1.4548796 | Q16: =IF($J$13="english",AA16,AB16) -> + Cash & equivalent | R16: ='FS Year'!M33 -> 136.05265 | S16: ='FS Year'!N33 -> 72.88629 | T16: ='FS Year'!O33 -> 776.33899 | U16: ='FS Year'!Q33 -> #REF! | V16: ='FS Year'!R33 -> #REF! | Y16: - Cost of goods sold | Z16: - Giá vốn hàng bán | AA16: + Cash & equivalent | AB16: + Tiền và tương đương
J17: =IF($J$13="english",Y17,Z17) -> Gross profit | K17: ='FS Year'!M12 -> 192.88479 | L17: ='FS Year'!N12 -> 205.93093 | M17: ='FS Year'!O12 -> 301.81521 | N17: ='FS Year'!Q12 -> 0.66 | O17: ='FS Year'!R12 -> 1.0516373 | Q17: =IF($J$13="english",AA17,AB17) -> + Short-term investments | R17: ='FS Year'!M34 -> 0 | S17: ='FS Year'!N34 -> 0 | T17: ='FS Year'!O34 -> 0 | U17: ='FS Year'!Q34 -> #REF! | V17: ='FS Year'!R34 -> #REF! | Y17: Gross profit | Z17: Lợi nhuận gộp | AA17: + Short-term investments | AB17: + Đầu tư TC ngắn hạn
C18: Sector | J18: =IF($J$13="english",Y18,Z18) -> - Sales & marketing | K18: ='FS Year'!M13 -> -44.045725 | L18: ='FS Year'!N13 -> -62.49381 | M18: ='FS Year'!O13 -> -54.30247 | N18: ='FS Year'!Q13 -> -0.162 | O18: ='FS Year'!R13 -> -0.25330222 | Q18: =IF($J$13="english",AA18,AB18) -> + Accounts receivable | R18: ='FS Year'!M35 -> 125.80868 | S18: ='FS Year'!N35 -> 131.2453 | T18: ='FS Year'!O35 -> 119.20113 | U18: ='FS Year'!Q35 -> #REF! | V18: ='FS Year'!R35 -> #REF! | Y18: - Sales & marketing | Z18: - Chi phí bán hàng | AA18: + Accounts receivable | AB18: + Các khoản phải thu
J19: =IF($J$13="english",Y19,Z19) -> - General & admin | K19: ='FS Year'!M14 -> -78.67124 | L19: ='FS Year'!N14 -> -81.246045 | M19: ='FS Year'!O14 -> -82.327577 | N19: ='FS Year'!Q14 -> -0.108 | O19: ='FS Year'!R14 -> -0.15524975 | Q19: =IF($J$13="english",AA19,AB19) -> + Inventories | R19: ='FS Year'!M36 -> 129.20743 | S19: ='FS Year'!N36 -> 432.78726 | T19: ='FS Year'!O36 -> 499.21431 | U19: ='FS Year'!Q36 -> #REF! | V19: ='FS Year'!R36 -> #REF! | Y19: - General & admin | Z19: - Chi phí quản lí DN | AA19: + Inventories | AB19: + Hàng tồn kho
C20: Key indicators | J20: =IF($J$13="english",Y20,Z20) -> Operating profit | K20: ='FS Year'!M15 -> 70.167824 | L20: ='FS Year'!N15 -> 62.191073 | M20: ='FS Year'!O15 -> 165.18516 | N20: ='FS Year'!Q15 -> 0.39 | O20: ='FS Year'!R15 -> 0.6430853 | Q20: =IF($J$13="english",AA20,AB20) -> + Other current assets | R20: ='FS Year'!M37 -> 189.55619 | S20: ='FS Year'!N37 -> 297.11363 | T20: ='FS Year'!O37 -> 284.11639 | U20: ='FS Year'!Q37 -> #REF! | V20: ='FS Year'!R37 -> #REF! | Y20: Operating profit | Z20: Lợi nhuận thuần HĐKD | AA20: + Other current assets | AB20: + Tài sản ngắn hạn khác
C21: Current price | F21: =Price!C382 -> 15700 | J21: =IF($J$13="english",Y21,Z21) -> - Forex gains/(losses) | K21: ='FS Year'!M16 -> 0.042025 | L21: ='FS Year'!N16 -> 0 | M21: ='FS Year'!O16 -> 0 | N21: ='FS Year'!Q16 -> 0.093 | O21: ='FS Year'!R16 -> 0.10465975 | Q21: =IF($J$13="english",AA21,AB21) -> Total current assets | R21: ='FS Year'!M38 -> 580.62496 | S21: ='FS Year'!N38 -> 934.03248 | T21: ='FS Year'!O38 -> 1678.8708 | U21: ='FS Year'!Q38 -> #REF! | V21: ='FS Year'!R38 -> #REF! | Y21: - Forex gains/(losses) | Z21: - (Lỗ) / lại tỷ giá | AA21: Total current assets | AB21: Tổng tài sản ngắn hạn
J22: =IF($J$13="english",Y22,Z22) -> - Net non-op gains | K22: ='FS Year'!M17 -> 15.520407 | L22: ='FS Year'!N17 -> 58.6378 | M22: ='FS Year'!O17 -> 101.26315 | N22: ='FS Year'!Q17 -> 0.123 | O22: ='FS Year'!R17 -> 0.10619569 | Q22: =IF($J$13="english",AA22,AB22) -> + Gross fixed assets | R22: ='FS Year'!M39 -> 46.413282 | S22: ='FS Year'!N39 -> 44.852805 | T22: ='FS Year'!O39 -> 42.124221 | U22: ='FS Year'!Q39 -> #REF! | V22: ='FS Year'!R39 -> #REF! | Y22: - Net non-op gains | Z22: - Lợi nhuận khác | AA22: + Gross fixed assets | AB22: + Tài sản dài hạn
C23: 52-week low | F23: =MIN(Price!C17:C382) -> 7592.43 | J23: =IF($J$13="english",Y23,Z23) -> EBIT | K23: ='FS Year'!M18 -> 85.730256 | L23: ='FS Year'!N18 -> 120.82887 | M23: ='FS Year'!O18 -> 266.44832 | N23: ='FS Year'!Q18 -> 0.606 | O23: ='FS Year'!R18 -> 0.85394073 | Q23: =IF($J$13="english",AA23,AB23) -> - Accum. depreciation | R23: ='FS Year'!M40 -> -8.9248649 | S23: ='FS Year'!N40 -> -9.2843747 | T23: ='FS Year'!O40 -> -9.8412946 | U23: ='FS Year'!Q40 -> #REF! | V23: ='FS Year'!R40 -> #REF! | Y23: EBIT | Z23: Lợi nhuận khác | AA23: - Accum. depreciation | AB23: + Khấu hao lũy kế
C24: 52-week high | F24: =MAX(Price!C17:C382) -> 17500 | J24: =IF($J$13="english",Y24,Z24) -> - Interest expense | K24: ='FS Year'!M19 -> -6.6164557 | L24: ='FS Year'!N19 -> -0.342829 | M24: ='FS Year'!O19 -> -0.0792907 | N24: ='FS Year'!Q19 -> -0.009 | O24: ='FS Year'!R19 -> -0.032702591 | Q24: =IF($J$13="english",AA24,AB24) -> + Net fixed assets | R24: ='FS Year'!M41 -> 37.488417 | S24: ='FS Year'!N41 -> 35.56843 | T24: ='FS Year'!O41 -> 32.282926 | U24: ='FS Year'!Q41 -> #REF! | V24: ='FS Year'!R41 -> #REF! | Y24: - Interest expense | Z24: - Chi phí lãi vay | AA24: + Net fixed assets | AB24: + Tài sản dài hạn
C25: Avg 30-day trading vol | F25: =AVERAGE(Price!L17:L46) -> 530328.67 | J25: =IF($J$13="english",Y25,Z25) -> EBT | K25: ='FS Year'!M20 -> 79.1138 | L25: ='FS Year'!N20 -> 120.48604 | M25: ='FS Year'!O20 -> 266.36903 | N25: ='FS Year'!Q20 -> 0.597 | O25: ='FS Year'!R20 -> 0.82123814 | Q25: =IF($J$13="english",AA25,AB25) -> + Long-term investments | R25: ='FS Year'!M42 -> 110.14465 | S25: ='FS Year'!N42 -> 110.14465 | T25: ='FS Year'!O42 -> 0 | U25: ='FS Year'!Q42 -> #REF! | V25: ='FS Year'!R42 -> #REF! | Y25: EBT | Z25: Lợi nhuận trước thuế | AA25: + Long-term investments | AB25: + Đầu tư tài chính dài hạn
C26: Outstanding shares (mn) | E26: =_xll.BDH(ticker,"EQY_SH_OUT",C11-1,C11,"Dir=H","Dts=H","Sort=A","Quote=C","QtTyp=Y","Days=A","Per=cd","DtFmt=D","Fill=P","cols=2;rows=1") -> #NAME? | F26: 75 | J26: =IF($J$13="english",Y26,Z26) -> - Income tax expense | K26: ='FS Year'!M21 -> -20.018952 | L26: ='FS Year'!N21 -> -30.756144 | M26: ='FS Year'!O21 -> -53.321005 | N26: ='FS Year'!Q21 -> -0.095 | O26: ='FS Year'!R21 -> -0.15681483 | Q26: =IF($J$13="english",AA26,AB26) -> + Other long-term assets | R26: ='FS Year'!M43 -> 88.194154 | S26: ='FS Year'!N43 -> 188.4695 | T26: ='FS Year'!O43 -> 449.29909 | U26: ='FS Year'!Q43 -> #REF! | V26: ='FS Year'!R43 -> #REF! | Y26: - Income tax expense | Z26: - Thuế TNDN | AA26: + Other long-term assets | AB26: + Tài sản dài hạn khác
C27: Market cap (VND billion) | F27: =price*shares/unit -> 1177.5 | J27: =IF($J$13="english",Y27,Z27) -> Profit after tax | K27: ='FS Year'!M22 -> 59.094848 | L27: ='FS Year'!N22 -> 89.7299 | M27: ='FS Year'!O22 -> 213.04802 | N27: ='FS Year'!Q22 -> 0.446 | O27: ='FS Year'!R22 -> 0.63027029 | Q27: =IF($J$13="english",AA27,AB27) -> Total long-term assets | R27: ='FS Year'!M44 -> 235.82722 | S27: ='FS Year'!N44 -> 334.18258 | T27: ='FS Year'!O44 -> 481.58202 | U27: ='FS Year'!Q44 -> #REF! | V27: ='FS Year'!R44 -> #REF! | Y27: Profit after tax | Z27: LNST | AA27: Total long-term assets | AB27: Tổng tài sản dài hạn
C28: Market cap (USD million) | F28: =F27/F10*10^3 -> 56.071429 | J28: =IF($J$13="english",Y28,Z28) -> - Minority interests | K28: ='FS Year'!M23 -> -1.234897 | L28: ='FS Year'!N23 -> -6.9659064 | M28: ='FS Year'!O23 -> -45.213531 | N28: ='FS Year'!Q23 -> -0.109 | O28: ='FS Year'!R23 -> -0.12721978 | Q28: =IF($J$13="english",AA28,AB28) -> Total Assets | R28: ='FS Year'!M45 -> 816.45218 | S28: ='FS Year'!N45 -> 1268.2151 | T28: ='FS Year'!O45 -> 2160.4528 | U28: ='FS Year'!Q45 -> #REF! | V28: ='FS Year'!R45 -> #REF! | Y28: - Minority interests | Z28: - Lợi ích cổ đông thiểu số | AA28: Total Assets | AB28: Tổng Tài sản
C29: Foreign ownership % | E29: =_xll.BDH(ticker,"TOTAL_FOREIGN_PER_SHR_TOT",C11-1,C11,"Dir=H","Dts=H","Sort=A","Quote=C","QtTyp=Y","Days=A","Per=cd","DtFmt=D","Fill=P","cols=2;rows=1")/100 -> #NAME? | F29: 24.81 | J29: =IF($J$13="english",Y29,Z29) -> Net Income to common | K29: ='FS Year'!M24 -> 57.859951 | L29: ='FS Year'!N24 -> 82.763994 | M29: ='FS Year'!O24 -> 167.83449 | N29: ='FS Year'!Q24 -> 0.337 | O29: ='FS Year'!R24 -> 0.50305051 | Y29: Net Income to common | Z29: LNST của cổ đông CT Mẹ
J30: =IF($J$13="english",Y30,Z30) -> EPS | K30: ='FS Year'!M25 -> 1251.026 | L30: ='FS Year'!N25 -> 1396.8654 | M30: ='FS Year'!O25 -> 2101.2195 | N30: ='FS Year'!Q25 -> #REF! | O30: ='FS Year'!R25 -> #REF! | Q30: =IF($J$13="english",AA30,AB30) -> Liabilities & Equity | Y30: EPS | Z30: EPS (đ) | AA30: Liabilities & Equity | AB30: Nợ & Vốn chủ sở hữu
D31: =L14 -> 2023 | E31: =M14 -> 2024 | F31: =N14&"F" -> 2025F | J31: =IF($J$13="english",Y31,Z31) -> EBITDA | K31: ='FS Year'!M27 -> 88.689436 | L31: ='FS Year'!N27 -> 123.02123 | M31: ='FS Year'!O27 -> 268.74592 | N31: ='FS Year'!Q27 -> 0.3953 | O31: ='FS Year'!R27 -> 0.6469853 | Q31: =IF($J$13="english",AA31,AB31) -> + Accounts payable | R31: ='FS Year'!M48 -> 35.76286 | S31: ='FS Year'!N48 -> 21.303074 | T31: ='FS Year'!O48 -> 55.022482 | U31: ='FS Year'!Q48 -> #REF! | V31: ='FS Year'!R48 -> #REF! | Y31: EBITDA | Z31: EBITDA | AA31: + Accounts payable | AB31: + Phải trả ngắn hạn
C32: EPS (basic) | D32: ='FS Year'!N25 -> 1396.8654 | E32: ='FS Year'!O25 -> 2101.2195 | F32: ='FS Year'!Q25 -> #REF! | J32: =IF($J$13="english",Y32,Z32) -> Depreciation | K32: ='FS Year'!M28 -> -2.9591801 | L32: ='FS Year'!N28 -> -2.192354 | M32: ='FS Year'!O28 -> -2.2976035 | N32: ='FS Year'!Q28 -> -0.0053 | O32: ='FS Year'!R28 -> -0.0039 | Q32: =IF($J$13="english",AA32,AB32) -> + Short-term borrowings | R32: ='FS Year'!M49 -> 0.45 | S32: ='FS Year'!N49 -> 0 | T32: ='FS Year'!O49 -> 1 | U32: ='FS Year'!Q49 -> #REF! | V32: ='FS Year'!R49 -> #REF! | Y32: Depreciation | Z32: Khấu hao | AA32: + Short-term borrowings | AB32: + Vay và nợ ngắn hạn
C33: EPS growth % | D33: ='FS Year'!N188*100 -> 11.657582 | E33: ='FS Year'!P188*100 -> 0 | F33: ='FS Year'!Q188*100 -> 0 | J33: =IF($J$13="english",Y33,Z33) -> Revenue growth % | K33: ='FS Year'!M173 -> 0.40894671 | L33: ='FS Year'!N173 -> -0.1509576 | M33: ='FS Year'!O173 -> 0.47750656 | N33: ='FS Year'!Q173 -> -0.99724407 | O33: ='FS Year'!R173 -> 0.79678628 | Q33: =IF($J$13="english",AA33,AB33) -> + Other ST liabilities | R33: ='FS Year'!M50 -> 196.74578 | S33: ='FS Year'!N50 -> 509.92335 | T33: ='FS Year'!O50 -> 909.34067 | U33: ='FS Year'!Q50 -> #REF! | V33: ='FS Year'!R50 -> #REF! | Y33: Revenue growth % | Z33: Tăng trưởng doanh thu | AA33: + Other ST liabilities | AB33: + Phải trả ngắn hạn khác
C34: Dividend yield % | D34: ='FS Year'!N92*100 -> 0.28184399 | E34: ='FS Year'!O92*100 -> 1.6608902 | F34: ='FS Year'!Q92*100 -> #REF! | J34: =IF($J$13="english",Y34,Z34) -> Operating profit growth % | K34: ='FS Year'!M178 -> -0.090226628 | L34: ='FS Year'!N178 -> -0.11368104 | M34: ='FS Year'!O178 -> 1.6560912 | N34: ='FS Year'!Q178 -> -0.99763901 | O34: ='FS Year'!R178 -> 0.64893666 | Q34: =IF($J$13="english",AA34,AB34) -> Current liabilities | R34: ='FS Year'!M51 -> 232.95864 | S34: ='FS Year'!N51 -> 531.22642 | T34: ='FS Year'!O51 -> 965.36315 | U34: ='FS Year'!Q51 -> #REF! | V34: ='FS Year'!R51 -> #REF! | Y34: Operating profit growth % | Z34: Tăng trưởng LN HĐKD | AA34: Current liabilities | AB34: Nợ ngắn hạn
C35: P/E x (mkt. price) | D35: ='FS Year'!N138 -> 10.14348 | E35: ='FS Year'!P138 -> 0 | F35: ='FS Year'!Q138 -> 0 | J35: =IF($J$13="english",Y35,Z35) -> EBIT growth % | K35: ='FS Year'!M181 -> -0.087468678 | L35: ='FS Year'!N181 -> 0.40940759 | M35: ='FS Year'!O181 -> 1.2051709 | N35: ='FS Year'!Q181 -> -0.99772564 | O35: ='FS Year'!R181 -> 0.40914312 | Q35: =IF($J$13="english",AA35,AB35) -> + Long-term debt | R35: ='FS Year'!M52 -> 0.11576 | S35: ='FS Year'!N52 -> 69.714 | T35: ='FS Year'!O52 -> 119.10941 | U35: ='FS Year'!Q52 -> #REF! | V35: ='FS Year'!R52 -> #REF! | Y35: EBIT growth % | Z35: Tăng trưởng EBIT % | AA35: + Long-term debt | AB35: + Vay và nợ dài hạn
C36: P/B x (mkt. price) | D36: ='FS Year'!N139 -> 1.6574717 | E36: ='FS Year'!P139 -> 0 | F36: ='FS Year'!Q139 -> 0 | J36: =IF($J$13="english",Y36,Z36) -> EPS growth % | K36: ='FS Year'!M188 -> 0.526169 | L36: ='FS Year'!N188 -> 0.11657582 | M36: ='FS Year'!O188 -> 0.50423912 | N36: ='FS Year'!Q188 -> 0 | O36: ='FS Year'!R188 -> 0 | Q36: =IF($J$13="english",AA36,AB36) -> + Other LT liabilities | R36: ='FS Year'!M53 -> 3.7836345 | S36: ='FS Year'!N53 -> 3.6598596 | T36: ='FS Year'!O53 -> 3.752779 | U36: ='FS Year'!Q53 -> #REF! | V36: ='FS Year'!R53 -> #REF! | Y36: EPS growth % | Z36: Tăng trưởng EPS % | AA36: + Other LT liabilities | AB36: + Phải trả dài hạn
C37: EV / EBITDA x | D37: ='FS Year'!N140 -> 7.0461371 | E37: ='FS Year'!P140 -> 0 | F37: ='FS Year'!Q140 -> 0 | J37: =IF($J$13="english",Y37,Z37) -> Profitability ratios | K37: =K14 -> 2022 | L37: =L14 -> 2023 | M37: =M14 -> 2024 | N37: =N14 -> 2025 | O37: =O14 -> 2026 | Q37: =IF($J$13="english",AA37,AB37) -> Total LT liabilities | R37: ='FS Year'!M54 -> 3.8993945 | S37: ='FS Year'!N54 -> 73.37386 | T37: ='FS Year'!O54 -> 122.86219 | U37: ='FS Year'!Q54 -> #REF! | V37: ='FS Year'!R54 -> #REF! | Y37: Profitability ratios | Z37: Chỉ số khả năng sinh lợi | AA37: Total LT liabilities | AB37: Nợ dài hạn
C38: ROE % | D38: ='FS Year'!N112*100 -> 14.435208 | E38: ='FS Year'!P112*100 -> 0 | F38: ='FS Year'!Q112*100 -> 0 | J38: =IF($J$13="english",Y38,Z38) -> Gross margin | K38: ='FS Year'!M108 -> 0.47802568 | L38: ='FS Year'!N108 -> 0.60109823 | M38: ='FS Year'!O108 -> 0.59625986 | N38: ='FS Year'!Q108 -> 0.47311828 | O38: ='FS Year'!R108 -> 0.41956122 | Q38: =IF($J$13="english",AA38,AB38) -> Total Liabilities | R38: ='FS Year'!M55 -> 236.85803 | S38: ='FS Year'!N55 -> 604.60028 | T38: ='FS Year'!O55 -> 1088.2253 | U38: ='FS Year'!Q55 -> #REF! | V38: ='FS Year'!R55 -> #REF! | Y38: Gross margin | Z38: Tỷ suất lợi nhuận gộp | AA38: Total Liabilities | AB38: Tổng nợ
C39: ROA % | D39: ='FS Year'!N113*100 -> 8.6085585 | E39: ='FS Year'!P113*100 -> 0 | F39: ='FS Year'!Q113*100 -> 0 | J39: =IF($J$13="english",Y39,Z39) -> Profit after tax margin | K39: ='FS Year'!M111 -> 0.14645455 | L39: ='FS Year'!N111 -> 0.26191541 | M39: ='FS Year'!O111 -> 0.42089325 | N39: ='FS Year'!Q111 -> 0.31971326 | O39: ='FS Year'!R111 -> 0.25145264 | Q39: =IF($J$13="english",AA39,AB39) -> + Total preferred equity | R39: ='FS Year'!M56 -> 0 | S39: ='FS Year'!N56 -> 0 | T39: ='FS Year'!O56 -> 0 | U39: ='FS Year'!Q56 -> #REF! | V39: ='FS Year'!R56 -> #REF! | Y39: Profit after tax margin | Z39: Tỷ suất LNST | AA39: + Total preferred equity | AB39: + Cổ phiếu ưu đãi
C40: ROIC % | D40: ='FS Year'!N119*100 -> 13.662836 | E40: ='FS Year'!P119*100 -> 0 | F40: ='FS Year'!Q119*100 -> 0 | J40: =IF($J$13="english",Y40,Z40) -> ROE Dupont | K40: ='FS Year'!M112 -> 0.11399803 | L40: ='FS Year'!N112 -> 0.14435208 | M40: ='FS Year'!O112 -> 0.24546933 | N40: ='FS Year'!Q112 -> 0 | O40: ='FS Year'!R112 -> 0 | Q40: =IF($J$13="english",AA40,AB40) -> + Addt’l paid in capital | R40: ='FS Year'!M57 -> 31.980271 | S40: ='FS Year'!N57 -> 10.982381 | T40: ='FS Year'!O57 -> 10.867981 | U40: ='FS Year'!Q57 -> #REF! | V40: ='FS Year'!R57 -> #REF! | Y40: ROE Dupont | Z40: ROE DuPont | AA40: + Addt’l paid in capital | AB40: + Thặng dư
C41: Debt-to-equity % | D41: ='FS Year'!N133 -> 0.10505191 | E41: ='FS Year'!P133 -> 0 | F41: ='FS Year'!Q133 -> 0 | J41: =IF($J$13="english",Y41,Z41) -> ROA Dupont | K41: ='FS Year'!M113 -> 0.069413276 | L41: ='FS Year'!N113 -> 0.086085585 | M41: ='FS Year'!O113 -> 0.12427452 | N41: ='FS Year'!Q113 -> 0 | O41: ='FS Year'!R113 -> 0 | Q41: =IF($J$13="english",AA41,AB41) -> + Share capital | R41: ='FS Year'!M58 -> 420 | S41: ='FS Year'!N58 -> 527.99681 | T41: ='FS Year'!O58 -> 750 | U41: ='FS Year'!Q58 -> #REF! | V41: ='FS Year'!R58 -> #REF! | Y41: ROA Dupont | Z41: ROA DuPont | AA41: + Share capital | AB41: + Vốn điều lệ
J42: =IF($J$13="english",Y42,Z42) -> * EBIT Margin | K42: ='FS Year'!M114 -> 0.21246499 | L42: ='FS Year'!N114 -> 0.35269118 | M42: ='FS Year'!O114 -> 0.52638976 | N42: ='FS Year'!Q114 -> 0.4344086 | O42: ='FS Year'!R114 -> 0.34068821 | Q42: =IF($J$13="english",AA42,AB42) -> + Retained earnings | R42: ='FS Year'!M59 -> 103.75583 | S42: ='FS Year'!N59 -> 94.153804 | T42: ='FS Year'!O59 -> 241.89213 | U42: ='FS Year'!Q59 -> #REF! | V42: ='FS Year'!R59 -> #REF! | Y42: * EBIT Margin | Z42: Tỷ suất EBIT | AA42: + Retained earnings | AB42: + LN chưa phân phối
C43: Price performance % | D43: 3M | E43: 6M | F43: 12M | J43: =IF($J$13="english",Y43,Z43) -> * Tax burden | K43: ='FS Year'!M115 -> 0.74696005 | L43: ='FS Year'!N115 -> 0.74473273 | M43: ='FS Year'!O115 -> 0.7998228 | N43: ='FS Year'!Q115 -> 0.74706868 | O43: ='FS Year'!R115 -> 0.76746349 | Q43: =IF($J$13="english",AA43,AB43) -> + Minority interest | R43: ='FS Year'!M60 -> 23.858045 | S43: ='FS Year'!N60 -> 30.481793 | T43: ='FS Year'!O60 -> 69.467376 | U43: ='FS Year'!Q60 -> #REF! | V43: ='FS Year'!R60 -> #REF! | Y43: * Tax burden | Z43: LNTT / LNST | AA43: + Minority interest | AB43: + Lợi ích cổ đông thiểu số
C44: =C7 -> DXG | D44: =Price!G11*100 -> 5.3691275 | E44: =Price!H11*100 -> 21.705426 | F44: =Price!I11*100 -> 75.317526 | J44: =IF($J$13="english",Y44,Z44) -> * Interest burden | K44: ='FS Year'!M116 -> 0.9228224 | L44: ='FS Year'!N116 -> 0.99716269 | M44: ='FS Year'!O116 -> 0.99970242 | N44: ='FS Year'!Q116 -> 0.98514851 | O44: ='FS Year'!R116 -> 0.96170391 | Q44: =IF($J$13="english",AA44,AB44) -> Total equity | R44: ='FS Year'!M61 -> 579.59414 | S44: ='FS Year'!N61 -> 663.61479 | T44: ='FS Year'!O61 -> 1072.2275 | U44: ='FS Year'!Q61 -> #REF! | V44: ='FS Year'!R61 -> #REF! | Y44: * Interest burden | Z44: LNTT / EBIT | AA44: Total equity | AB44: Vốn chủ sở hữu
C45: Relative to Index | D45: =Price!G12*100 -> 1.8426968 | E45: =Price!H12*100 -> 9.6126945 | F45: =Price!I12*100 -> 56.077931 | J45: =IF($J$13="english",Y45,Z45) -> * Asset turnover | K45: ='FS Year'!M117 -> 0.4739578 | L45: ='FS Year'!N117 -> 0.32867705 | M45: ='FS Year'!O117 -> 0.29526374 | N45: ='FS Year'!Q117 -> 0 | O45: ='FS Year'!R117 -> 0 | Q45: =IF($J$13="english",AA45,AB45) -> Liabilities & equity | R45: ='FS Year'!M62 -> 816.45218 | S45: ='FS Year'!N62 -> 1268.2151 | T45: ='FS Year'!O62 -> 2160.4528 | U45: ='FS Year'!Q62 -> #REF! | V45: ='FS Year'!R62 -> #REF! | Y45: * Asset turnover | Z45: Vòng quay tổng tài sản | AA45: Liabilities & equity | AB45: Tổng cộng nguồn vốn
J46: =IF($J$13="english",Y46,Z46) -> Leverage ratio | K46: ='FS Year'!M118 -> 1.6423088 | L46: ='FS Year'!N118 -> 1.6768438 | M46: ='FS Year'!O118 -> 1.9752186 | N46: ='FS Year'!Q118 -> 0 | O46: ='FS Year'!R118 -> 0 | Y46: Leverage ratio | Z46: Đòn bẩy tài chính
